<?xml version='1.0'?>
   <sdf version='1.4'>
     <model name="train">

       <include>
         <uri>model://carriage</uri>
         <name>car_1</name>
         <pose>0 0 0 0 0 0</pose>
       </include>

       <include>
         <uri>model://carriage</uri>
         <name>car_2</name>
         <pose>0 -0.6 0 0 0 0</pose>
       </include>

       <include>
         <uri>model://carriage</uri>
         <name>car_3</name>
         <pose>0 -1.2 0 0 0 0</pose>
       </include>

       <include>
         <uri>model://carriage</uri>
         <name>car_4</name>
         <pose>0 -1.8 0 0 0 0</pose>
       </include>

       <include>
         <uri>model://carriage</uri>
         <name>car_5</name>
         <pose>0 -2.4 0 0 0 0</pose>
       </include>

       <link name="connection_1">
         <pose> 0 -0.3 0.1 1.5707 0 0 </pose>
          <visual name="visual">
            <geometry>
              <cylinder>
                <radius>0.005</radius>
                <length>0.3</length>
              </cylinder>
            </geometry>
          </visual>
       </link>

       <link name="connection_2">
         <pose> 0 -0.9 0.1 1.5707 0 0 </pose>
          <visual name="visual">
            <geometry>
              <cylinder>
                <radius>0.005</radius>
                <length>0.3</length>
              </cylinder>
            </geometry>
          </visual>
       </link>

       <link name="connection_3">
         <pose> 0 -1.5 0.1 1.5707 0 0 </pose>
          <visual name="visual">
            <geometry>
              <cylinder>
                <radius>0.005</radius>
                <length>0.3</length>
              </cylinder>
            </geometry>
          </visual>
       </link>

       <link name="connection_4">
         <pose> 0 -2.1 0.1 1.5707 0 0 </pose>
          <visual name="visual">
            <geometry>
              <cylinder>
                <radius>0.005</radius>
                <length>0.3</length>
              </cylinder>
            </geometry>
          </visual>
       </link>

       <joint name='car_con_1' type='revolute'>
         <pose>0 0 -0.15 0 -0 0</pose>
         <child>car_1::chassis</child>
         <parent>connection_1</parent>
         <axis>
           <xyz>0 0 1</xyz>
           <use_parent_model_frame>1</use_parent_model_frame>
           <limit>
             <lower>-0.52</lower>
             <upper>0.52</upper>
           </limit>
         </axis>
       </joint>

         <joint name='car_con_2' type='revolute'>
           <pose>0 0 0.15 0 -0 0</pose>
           <child>car_2::chassis</child>
           <parent>connection_1</parent>
           <axis>
             <xyz>0 0 1</xyz>
             <use_parent_model_frame>1</use_parent_model_frame>
           <limit>
             <lower>-0.52</lower>
             <upper>0.52</upper>
           </limit>
         </axis>
         </joint>

         <joint name='car_con_3' type='revolute'>
           <pose>0 0 -0.15 0 -0 0</pose>
           <child>car_2::chassis</child>
           <parent>connection_2</parent>
           <axis>
             <xyz>0 0 1</xyz>
             <use_parent_model_frame>1</use_parent_model_frame>
             <limit>
               <lower>-0.52</lower>
               <upper>0.52</upper>
             </limit>
           </axis>
         </joint>

           <joint name='car_con_4' type='revolute'>
             <pose>0 0 0.15 0 -0 0</pose>
             <child>car_3::chassis</child>
             <parent>connection_2</parent>
             <axis>
               <xyz>0 0 1</xyz>
               <use_parent_model_frame>1</use_parent_model_frame>
             <limit>
               <lower>-0.52</lower>
               <upper>0.52</upper>
             </limit>
           </axis>
           </joint>

           <joint name='car_con_5' type='revolute'>
             <pose>0 0 -0.15 0 -0 0</pose>
             <child>car_3::chassis</child>
             <parent>connection_3</parent>
             <axis>
               <xyz>0 0 1</xyz>
               <use_parent_model_frame>1</use_parent_model_frame>
               <limit>
                 <lower>-0.52</lower>
                 <upper>0.52</upper>
               </limit>
             </axis>
           </joint>

             <joint name='car_con_6' type='revolute'>
               <pose>0 0 0.15 0 -0 0</pose>
               <child>car_4::chassis</child>
               <parent>connection_3</parent>
               <axis>
                 <xyz>0 0 1</xyz>
                 <use_parent_model_frame>1</use_parent_model_frame>
               <limit>
                 <lower>-0.52</lower>
                 <upper>0.52</upper>
               </limit>
             </axis>
             </joint>

             <joint name='car_con_7' type='revolute'>
               <pose>0 0 -0.15 0 -0 0</pose>
               <child>car_4::chassis</child>
               <parent>connection_4</parent>
               <axis>
                 <xyz>0 0 1</xyz>
                 <use_parent_model_frame>1</use_parent_model_frame>
                 <limit>
                   <lower>-0.52</lower>
                   <upper>0.52</upper>
                 </limit>
               </axis>
             </joint>

               <joint name='car_con_8' type='revolute'>
                 <pose>0 0 0.15 0 -0 0</pose>
                 <child>car_5::chassis</child>
                 <parent>connection_4</parent>
                 <axis>
                   <xyz>0 0 1</xyz>
                   <use_parent_model_frame>1</use_parent_model_frame>
                 <limit>
                   <lower>-0.52</lower>
                   <upper>0.52</upper>
                 </limit>
               </axis>
               </joint>

    </model>
   </sdf>
