<?xml version='1.0'?>
   <sdf version='1.4'>
     <model name="train">

       <include>
         <uri>model://carriage</uri>
         <name>car_1</name>
         <pose>0 0 0 0 0 0</pose>
       </include>

       <include>
         <uri>model://carriage</uri>
         <name>car_2</name>
         <pose>0 -0.6 0 0 0 0</pose>
       </include>

       <include>
         <uri>model://carriage</uri>
         <name>car_3</name>
         <pose>0 -1.2 0 0 0 0</pose>
       </include>

       <include>
         <uri>model://carriage</uri>
         <name>car_4</name>
         <pose>0 -1.8 0 0 0 0</pose>
       </include>

       <include>
         <uri>model://carriage</uri>
         <name>car_5</name>
         <pose>0 -2.4 0 0 0 0</pose>
       </include>

       <link name="connection_1">
         <pose> 0 -0.3 0.1 1.5707 0 0 </pose>
          <visual name="visual">
            <geometry>
              <cylinder>
                <radius>0.005</radius>
                <length>0.3</length>
              </cylinder>
            </geometry>
          </visual>
       </link>

       <joint name='car_con_1' type='revolute'>
         <pose>0 0 -0.15 0 -0 0</pose>
         <child>car_1::chassis</child>
         <parent>connection_1</parent>
         <axis>
           <xyz>0 0 1</xyz>
           <use_parent_model_frame>1</use_parent_model_frame>
           <!-- <dynamics>
             <spring_reference>0</spring_reference>
           </dynamics> -->
           <limit>
             <lower>-0.52</lower>
             <upper>0.52</upper>
           </limit>
         </axis>
       </joint>

         <joint name='car_con_2' type='revolute'>
           <pose>0 0 0.15 0 -0 0</pose>
           <child>car_2::chassis</child>
           <parent>connection_1</parent>
           <axis>
             <xyz>0 0 1</xyz>
             <use_parent_model_frame>1</use_parent_model_frame>
             <!-- <dynamics>
               <spring_reference>0</spring_reference>
             </dynamics> -->
           <limit>
             <lower>-0.52</lower>
             <upper>0.52</upper>
           </limit>
         </axis>
         </joint>



<!-- <joint name="hokuyo_joint" type="revolute">
  <child>hokuyo::link</child>
  <parent>chassis</parent>
  <axis>
    <xyz>0 0 1</xyz>
    <limit>
      <upper>0</upper>
      <lower>0</lower>
    </limit>
  </axis>
</joint> -->

    </model>
   </sdf>
