<?xml version='1.0'?>
   <sdf version='1.4'>
     <model name="carriage">

      <!-- <static>true</static> -->
<!--  -->
      <link name='chassis'>
        <pose>0 0 .1 0 0 0</pose>
        <inertial>
          <mass>50</mass>
        </inertial>
        <collision name='collision'>
          <geometry>
            <box>
              <size>.3 .2 .1</size>
            </box>
          </geometry>
        </collision>

        <visual name='visual'>
          <geometry>
            <box>
              <size>.3 .2 .1</size>
            </box>
          </geometry>
        </visual>
      </link>

        <link name="left_wheel">
          <pose>-0.17 0 0.07 0 1.5707 0</pose>
          <inertial>
            <mass>10</mass>
          </inertial>
          <collision name="collision">
            <geometry>
              <cylinder>
                <radius>.07</radius>
                <length>.02</length>
              </cylinder>
            </geometry>
              <surface>
                <friction>
                  <ode>
                    <mu>100000</mu>
                    <mu2>100000</mu2>
                    <slip1>0</slip1>
                    <slip2>0</slip2>
                  </ode>
                </friction>
              </surface>
              <max_contacts>10</max_contacts>
          </collision>
          <visual name="visual">
            <geometry>
              <cylinder>
                <radius>.07</radius>
                <length>.02</length>
              </cylinder>
            </geometry>
          </visual>
        </link>

        <link name="right_wheel">
          <pose>0.17 0 0.07 0 1.5707 0</pose>
          <inertial>
            <mass>10</mass>
          </inertial>
          <collision name="collision">
            <geometry>
              <cylinder>
                <radius>.07</radius>
                <length>.02</length>
              </cylinder>
            </geometry>
              <surface>
                <friction>
                  <ode>
                    <mu>100000</mu>
                    <mu2>100000</mu2>
                    <slip1>0</slip1>
                    <slip2>0</slip2>
                  </ode>
                </friction>
              </surface>
              <max_contacts>10</max_contacts>
          </collision>
          <visual name="visual">
            <geometry>
              <cylinder>
                <radius>.07</radius>
                <length>.02</length>
              </cylinder>
            </geometry>
          </visual>
        </link>

        <joint name='left_wheel_joint' type='revolute'>
          <child>left_wheel</child>
          <parent>chassis</parent>
          <axis>
            <xyz>-1 0 0</xyz>
          </axis>
        </joint>

        <joint name='right_wheel_joint' type='revolute'>
          <child>right_wheel</child>
          <parent>chassis</parent>
          <axis>
            <xyz>-1 0 0</xyz>
          </axis>
        </joint>

    </model>
   </sdf>
